File: 先进材料表征技术与实验/表征技术课-实验结果/单层膜-XRD/single-XRD.ras
*RAS_DATA_START
*RAS_HEADER_START
*DISP_FMT_X "%.2f"
*DISP_FMT_Y "%.0f"
*DISP_FULLSCALE "4332140.3267999999"
*DISP_LINE_COLOR "255.0000000000"
*DISP_LINE_STYLE "0.0000000000"
*DISP_LINE_WIDTH "0.2500000000"
*DISP_NOTE "Collected Data-3"
*DISP_OFFSET_Y "0.0000000000"
*DISP_PEAKSEARCH_UNIT_Y "cps"
*DISP_RANGE_BOTTOM "0.0100000000"
*DISP_RANGE_LEFT "10.0000000000"
*DISP_RANGE_LOGCUTOFF "0.0100000000"
*DISP_RANGE_RIGHT "90.0000000000"
*DISP_RANGE_TOP "4332140.3267999999"
*DISP_SCALE_MODE_Y "2.0000000000"
*DISP_TAB_NAME "Theta/2-Theta"
*DISP_TITLE_Y "Intensity"
*DISP_UNIT_Y "cps"
*DISP_WINDOW_NAME "MSG_MACROENGINE"
*FILE_COMMENT " "
*FILE_MD5 ""
*FILE_MEMO " "
*FILE_OPERATOR "administrator"
*FILE_SAMPLE "inznsn"
*FILE_TYPE "RAS_RAW"
*FILE_USERGROUP "System Manager"
*FILE_VERSION "1.0000000000"
*HW_ATTACHMENT_ID "ATT0037"
*HW_ATTACHMENT_NAME "αβ試料台(反射)|Alpha Beta Stage - Refrection"
*HW_COUNTER_ID-0 "CUT0021"
*HW_COUNTER_ID-1 "CUT0020"
*HW_COUNTER_ID-2 ""
*HW_COUNTER_ID-3 "CSL0021"
*HW_COUNTER_ID-4 "CMC0021"
*HW_COUNTER_NAME-0 "SC-70|SC-70"
*HW_COUNTER_NAME-1 "None|None"
*HW_COUNTER_NAME-2 ""
*HW_COUNTER_NAME-3 "BBM|BBM"
*HW_COUNTER_NAME-4 "検出器モノクロメータ|Detector monochromator"
*HW_COUNTER_SELECT_NAME "SC-70|SC-70"
*HW_ECP_HV "618.5000000000"
*HW_ECP_HV_UNIT "V"
*HW_GONIOMETER_ID "GON0024"
*HW_GONIOMETER_NAME "SmartLab(In-plane)|SmartLab(In-plane)"
*HW_GONIOMETER_RADIUS-0 "90.0"
*HW_GONIOMETER_RADIUS-1 "114.0"
*HW_GONIOMETER_RADIUS-2 "190.0"
*HW_GONIOMETER_RADIUS-3 "300.0"
*HW_GONIOMETER_RADIUS-4 "187.0"
*HW_GONIOMETER_RADIUS-5 "300.0"
*HW_GONIOMETER_RADIUS-6 "113.0"
*HW_GONIOMETER_RADIUS-7 "331.0"
*HW_I_OPT_ID-0 "CBO0021"
*HW_I_OPT_ID-1 "ICR0023"
*HW_I_OPT_ID-2 "ISL0021"
*HW_I_OPT_ID-3 "ISO0021"
*HW_I_OPT_ID-4 "IAD0021"
*HW_I_OPT_ID-5 "IPR0001"
*HW_I_OPT_NAME-0 "CBOユニット|CBO unit"
*HW_I_OPT_NAME-1 "標準入射光学ユニット|Standard incident optical unit"
*HW_I_OPT_NAME-2 "標準入射スリットボックス|Standard incident slit box"
*HW_I_OPT_NAME-3 "入射平行スリット|Incident parallel slit"
*HW_I_OPT_NAME-4 "長手制限スリット|Length limiting slit"
*HW_I_OPT_NAME-5 "None|None"
*HW_R_ATTENUATER_AUTOMODE "1"
*HW_R_OPT_ID-0 "RSS0021"
*HW_R_OPT_ID-1 "RCR0022"
*HW_R_OPT_ID-2 "RSO0021"
*HW_R_OPT_ID-3 "RRS0021"
*HW_R_OPT_ID-4 "ATN0021"
*HW_R_OPT_ID-5 "RFL0021"
*HW_R_OPT_ID-6 "RAD0021"
*HW_R_OPT_NAME-0 "標準受光スリットボックス1|Standard receiving slit box # 1"
*HW_R_OPT_NAME-1 "標準受光光学ユニット1|Standard receiving unit # 1"
*HW_R_OPT_NAME-2 "標準受光光学ユニット2|Standard receiving optical unit # 2"
*HW_R_OPT_NAME-3 "標準受光スリットボックス2|Standard receiving slit box # 2"
*HW_R_OPT_NAME-4 "標準アッテネータ|Standard Attenuator"
*HW_R_OPT_NAME-5 "Cu Kβ|Cu K-beta"
*HW_R_OPT_NAME-6 "調整用受光スリット|Alignment receiving slit"
*HW_SAMPLE_HOLDER_ID "SMP0025"
*HW_SAMPLE_HOLDER_NAME "Zステージ単独|Z stage only"
*HW_XG_CURRENT_MAX "200"
*HW_XG_CURRENT_MIN "10"
*HW_XG_CURRENT_RESOLUTION "1"
*HW_XG_CURRENT_UNIT "mA"
*HW_XG_FOCUS "0.4mm x 8mm"
*HW_XG_FOCUS_TYPE "Normal"
*HW_XG_ID ""
*HW_XG_NAME "9kW 開放管(45kV 200mA ID:1700)|9kW Rotating anode(45kV 200mA ID:1700)"
*HW_XG_TARGET_ATOMIC_NUMBER "29.0000000000"
*HW_XG_TARGET_NAME "Cu"
*HW_XG_TYPE "Rota"
*HW_XG_VOLTAGE_MAX "45"
*HW_XG_VOLTAGE_MIN "20"
*HW_XG_VOLTAGE_RESOLUTION "1"
*HW_XG_VOLTAGE_UNIT "kV"
*HW_XG_WATT_MAX "9.00"
*HW_XG_WATT_UNIT "kW"
*HW_XG_WAVE_LENGTH_ALPHA1 "1.540593"
*HW_XG_WAVE_LENGTH_ALPHA2 "1.544414"
*HW_XG_WAVE_LENGTH_BETA "1.392250"
*MEAS_COND_AXIS_NAME-0 "Theta/2-Theta"
*MEAS_COND_AXIS_NAME-1 "2-Theta"
*MEAS_COND_AXIS_NAME-2 "Omega"
*MEAS_COND_AXIS_NAME-3 "2-Theta/Omega"
*MEAS_COND_AXIS_NAME-4 "Chi"
*MEAS_COND_AXIS_NAME-5 "Phi"
*MEAS_COND_AXIS_NAME-6 "2-ThetaChi"
*MEAS_COND_AXIS_NAME-7 "2-ThetaChi/Phi"
*MEAS_COND_AXIS_NAME-8 "Alpha"
*MEAS_COND_AXIS_NAME-9 "Beta"
*MEAS_COND_AXIS_NAME-10 "Gamma"
*MEAS_COND_AXIS_NAME-11 "Z"
*MEAS_COND_AXIS_NAME-12 "Attenuator"
*MEAS_COND_AXIS_NAME-13 "Theta_s"
*MEAS_COND_AXIS_NAME-14 "Theta_d"
*MEAS_COND_AXIS_NAME-15 "Ts"
*MEAS_COND_AXIS_NAME-16 "M"
*MEAS_COND_AXIS_NAME-17 "Incident slit"
*MEAS_COND_AXIS_NAME-18 ""
*MEAS_COND_AXIS_NAME-19 "Zs"
*MEAS_COND_AXIS_NAME-20 "Receiving slit # 1"
*MEAS_COND_AXIS_NAME-21 ""
*MEAS_COND_AXIS_NAME-22 "Receiving slit # 2"
*MEAS_COND_AXIS_NAME-23 ""
*MEAS_COND_AXIS_NAME-24 "Zd"
*MEAS_COND_AXIS_NAME-25 "CBO selection slit"
*MEAS_COND_AXIS_NAME-26 "Incident monochromator"
*MEAS_COND_AXIS_NAME-27 "Incident parallel slit"
*MEAS_COND_AXIS_NAME-28 "Length limiting slit"
*MEAS_COND_AXIS_NAME-29 "Center slit"
*MEAS_COND_AXIS_NAME-30 "Filter"
*MEAS_COND_AXIS_NAME-31 "Receiving optical device"
*MEAS_COND_AXIS_NAME-32 "Receiving parallel slit"
*MEAS_COND_AXIS_NAME-33 "Alignment receiving slit"
*MEAS_COND_AXIS_NAME-34 "Diffracted beam monochromator"
*MEAS_COND_AXIS_NAME-35 "Monochromator slit"
*MEAS_COND_AXIS_NAME-36 "2-ThetaB"
*MEAS_COND_AXIS_NAME-37 "Primary beam"
*MEAS_COND_AXIS_NAME-38 "HV"
*MEAS_COND_AXIS_NAME-39 "PHA"
*MEAS_COND_AXIS_NAME_INTERNAL-0 "TwoThetaTheta"
*MEAS_COND_AXIS_NAME_INTERNAL-1 "TwoTheta"
*MEAS_COND_AXIS_NAME_INTERNAL-2 "Omega"
*MEAS_COND_AXIS_NAME_INTERNAL-3 "TwoThetaOmega"
*MEAS_COND_AXIS_NAME_INTERNAL-4 "Chi"
*MEAS_COND_AXIS_NAME_INTERNAL-5 "Phi"
*MEAS_COND_AXIS_NAME_INTERNAL-6 "TwoThetaChi"
*MEAS_COND_AXIS_NAME_INTERNAL-7 "TwoThetaChiPhi"
*MEAS_COND_AXIS_NAME_INTERNAL-8 "Alpha"
*MEAS_COND_AXIS_NAME_INTERNAL-9 "Beta"
*MEAS_COND_AXIS_NAME_INTERNAL-10 "Gamma"
*MEAS_COND_AXIS_NAME_INTERNAL-11 "Z"
*MEAS_COND_AXIS_NAME_INTERNAL-12 "Attenuator"
*MEAS_COND_AXIS_NAME_INTERNAL-13 "ThetaS"
*MEAS_COND_AXIS_NAME_INTERNAL-14 "ThetaD"
*MEAS_COND_AXIS_NAME_INTERNAL-15 "Ts"
*MEAS_COND_AXIS_NAME_INTERNAL-16 "CBO-M"
*MEAS_COND_AXIS_NAME_INTERNAL-17 "IncidentSlitBox"
*MEAS_COND_AXIS_NAME_INTERNAL-18 "IncidentSlitBox-_Axis"
*MEAS_COND_AXIS_NAME_INTERNAL-19 "Zs"
*MEAS_COND_AXIS_NAME_INTERNAL-20 "ReceivingSlitBox1"
*MEAS_COND_AXIS_NAME_INTERNAL-21 "ReceivingSlitBox1-_Axis"
*MEAS_COND_AXIS_NAME_INTERNAL-22 "ReceivingSlitBox2"
*MEAS_COND_AXIS_NAME_INTERNAL-23 "ReceivingSlitBox2-_Axis"
*MEAS_COND_AXIS_NAME_INTERNAL-24 "ReceivingSlitBox2-Zd"
*MEAS_COND_AXIS_NAME_INTERNAL-25 "CBO"
*MEAS_COND_AXIS_NAME_INTERNAL-26 "IncidentMonochromator"
*MEAS_COND_AXIS_NAME_INTERNAL-27 "IncidentSollerSlit"
*MEAS_COND_AXIS_NAME_INTERNAL-28 "IncidentAxdSlit"
*MEAS_COND_AXIS_NAME_INTERNAL-29 "CenterSlit"
*MEAS_COND_AXIS_NAME_INTERNAL-30 "Filter"
*MEAS_COND_AXIS_NAME_INTERNAL-31 "ReceivingOptics"
*MEAS_COND_AXIS_NAME_INTERNAL-32 "ReceivingSollerSlit"
*MEAS_COND_AXIS_NAME_INTERNAL-33 "ReceivingAxdSlit"
*MEAS_COND_AXIS_NAME_INTERNAL-34 "CounterMonochromator"
*MEAS_COND_AXIS_NAME_INTERNAL-35 "CounterSlit"
*MEAS_COND_AXIS_NAME_INTERNAL-36 "TwoThetaB"
*MEAS_COND_AXIS_NAME_INTERNAL-37 "IncidentPrimary"
*MEAS_COND_AXIS_NAME_INTERNAL-38 "HV"
*MEAS_COND_AXIS_NAME_INTERNAL-39 "PHA"
*MEAS_COND_AXIS_NAME_MAGICNO-0 "83951616.0000000000"
*MEAS_COND_AXIS_NAME_MAGICNO-1 "268632064.0000000000"
*MEAS_COND_AXIS_NAME_MAGICNO-2 "268500992.0000000000"
*MEAS_COND_AXIS_NAME_MAGICNO-3 "83951616.0000000000"
*MEAS_COND_AXIS_NAME_MAGICNO-4 "268500992.0000000000"
*MEAS_COND_AXIS_NAME_MAGICNO-5 "268500992.0000000000"
*MEAS_COND_AXIS_NAME_MAGICNO-6 "268632064.0000000000"
*MEAS_COND_AXIS_NAME_MAGICNO-7 "83951616.0000000000"
*MEAS_COND_AXIS_NAME_MAGICNO-8 "17039360.0000000000"
*MEAS_COND_AXIS_NAME_MAGICNO-9 "17039360.0000000000"
*MEAS_COND_AXIS_NAME_MAGICNO-10 "131072.0000000000"
*MEAS_COND_AXIS_NAME_MAGICNO-11 "285278208.0000000000"
*MEAS_COND_AXIS_NAME_MAGICNO-12 "17301505.0000000000"
*MEAS_COND_AXIS_NAME_MAGICNO-13 "131072.0000000000"
*MEAS_COND_AXIS_NAME_MAGICNO-14 "131072.0000000000"
*MEAS_COND_AXIS_NAME_MAGICNO-15 "318898176.0000000000"
*MEAS_COND_AXIS_NAME_MAGICNO-16 "285343744.0000000000"
*MEAS_COND_AXIS_NAME_MAGICNO-17 "22020097.0000000000"
*MEAS_COND_AXIS_NAME_MAGICNO-18 "25165824.0000000000"
*MEAS_COND_AXIS_NAME_MAGICNO-19 "318898176.0000000000"
*MEAS_COND_AXIS_NAME_MAGICNO-20 "23068673.0000000000"
*MEAS_COND_AXIS_NAME_MAGICNO-21 "25165824.0000000000"
*MEAS_COND_AXIS_NAME_MAGICNO-22 "23068673.0000000000"
*MEAS_COND_AXIS_NAME_MAGICNO-23 "25165824.0000000000"
*MEAS_COND_AXIS_NAME_MAGICNO-24 "285343744.0000000000"
*MEAS_COND_AXIS_NAME_MAGICNO-25 "20971521.0000000000"
*MEAS_COND_AXIS_NAME_MAGICNO-26 "1.0000000000"
*MEAS_COND_AXIS_NAME_MAGICNO-27 "20971521.0000000000"
*MEAS_COND_AXIS_NAME_MAGICNO-28 "20971521.0000000000"
*MEAS_COND_AXIS_NAME_MAGICNO-29 "20971521.0000000000"
*MEAS_COND_AXIS_NAME_MAGICNO-30 "20971521.0000000000"
*MEAS_COND_AXIS_NAME_MAGICNO-31 "20971521.0000000000"
*MEAS_COND_AXIS_NAME_MAGICNO-32 "20971521.0000000000"
*MEAS_COND_AXIS_NAME_MAGICNO-33 "20971521.0000000000"
*MEAS_COND_AXIS_NAME_MAGICNO-34 "20971521.0000000000"
*MEAS_COND_AXIS_NAME_MAGICNO-35 "20971521.0000000000"
*MEAS_COND_AXIS_NAME_MAGICNO-36 "17039360.0000000000"
*MEAS_COND_AXIS_NAME_MAGICNO-37 "20971521.0000000000"
*MEAS_COND_AXIS_NAME_MAGICNO-38 "0.0000000000"
*MEAS_COND_AXIS_NAME_MAGICNO-39 "0.0000000000"
*MEAS_COND_AXIS_OFFSET-0 "-"
*MEAS_COND_AXIS_OFFSET-1 "-0.0090000000"
*MEAS_COND_AXIS_OFFSET-2 "-0.0952000000"
*MEAS_COND_AXIS_OFFSET-3 "-"
*MEAS_COND_AXIS_OFFSET-4 "0.0000000000"
*MEAS_COND_AXIS_OFFSET-5 "0.0000000000"
*MEAS_COND_AXIS_OFFSET-6 "0.0000000000"
*MEAS_COND_AXIS_OFFSET-7 "-"
*MEAS_COND_AXIS_OFFSET-8 "-"
*MEAS_COND_AXIS_OFFSET-9 "-"
*MEAS_COND_AXIS_OFFSET-10 "0.0000000000"
*MEAS_COND_AXIS_OFFSET-11 "-"
*MEAS_COND_AXIS_OFFSET-12 "-"
*MEAS_COND_AXIS_OFFSET-13 "-0.0952000000"
*MEAS_COND_AXIS_OFFSET-14 "0.0862000000"
*MEAS_COND_AXIS_OFFSET-15 "-"
*MEAS_COND_AXIS_OFFSET-16 "-"
*MEAS_COND_AXIS_OFFSET-17 "-"
*MEAS_COND_AXIS_OFFSET-18 "-"
*MEAS_COND_AXIS_OFFSET-19 "-"
*MEAS_COND_AXIS_OFFSET-20 "-"
*MEAS_COND_AXIS_OFFSET-21 "-"
*MEAS_COND_AXIS_OFFSET-22 "-"
*MEAS_COND_AXIS_OFFSET-23 "-"
*MEAS_COND_AXIS_OFFSET-24 "-"
*MEAS_COND_AXIS_OFFSET-25 "-"
*MEAS_COND_AXIS_OFFSET-26 "-"
*MEAS_COND_AXIS_OFFSET-27 "-"
*MEAS_COND_AXIS_OFFSET-28 "-"
*MEAS_COND_AXIS_OFFSET-29 "-"
*MEAS_COND_AXIS_OFFSET-30 "-"
*MEAS_COND_AXIS_OFFSET-31 "-"
*MEAS_COND_AXIS_OFFSET-32 "-"
*MEAS_COND_AXIS_OFFSET-33 "-"
*MEAS_COND_AXIS_OFFSET-34 "-"
*MEAS_COND_AXIS_OFFSET-35 "-"
*MEAS_COND_AXIS_OFFSET-36 "-"
*MEAS_COND_AXIS_OFFSET-37 "-"
*MEAS_COND_AXIS_OFFSET-38 "-"
*MEAS_COND_AXIS_OFFSET-39 "-"
*MEAS_COND_AXIS_POSITION-0 "10.0000000000"
*MEAS_COND_AXIS_POSITION-1 "9.9900000000"
*MEAS_COND_AXIS_POSITION-2 "4.9950000000"
*MEAS_COND_AXIS_POSITION-3 "9.9900000000"
*MEAS_COND_AXIS_POSITION-4 "0.0000000000"
*MEAS_COND_AXIS_POSITION-5 "0.0000000000"
*MEAS_COND_AXIS_POSITION-6 "0.0000000000"
*MEAS_COND_AXIS_POSITION-7 "0.0000000000"
*MEAS_COND_AXIS_POSITION-8 "90.0000000000"
*MEAS_COND_AXIS_POSITION-9 "0.0000000000"
*MEAS_COND_AXIS_POSITION-10 "0.0000000000"
*MEAS_COND_AXIS_POSITION-11 "0.4180200000"
*MEAS_COND_AXIS_POSITION-12 "1/10000"
*MEAS_COND_AXIS_POSITION-13 "4.9950000000"
*MEAS_COND_AXIS_POSITION-14 "4.9950000000"
*MEAS_COND_AXIS_POSITION-15 "0.1822500000"
*MEAS_COND_AXIS_POSITION-16 "0.0000000000"
*MEAS_COND_AXIS_POSITION-17 "2/3deg"
*MEAS_COND_AXIS_POSITION-18 "2.2088000000"
*MEAS_COND_AXIS_POSITION-19 "0.0256200000"
*MEAS_COND_AXIS_POSITION-20 "2/3deg"
*MEAS_COND_AXIS_POSITION-21 "1.3138000000"
*MEAS_COND_AXIS_POSITION-22 "0.450mm"
*MEAS_COND_AXIS_POSITION-23 "0.4500000000"
*MEAS_COND_AXIS_POSITION-24 "0.1993800000"
*MEAS_COND_AXIS_POSITION-25 "BB"
*MEAS_COND_AXIS_POSITION-26 "0.0000000000"
*MEAS_COND_AXIS_POSITION-27 "Soller_slit_5.0deg"
*MEAS_COND_AXIS_POSITION-28 "10.0mm"
*MEAS_COND_AXIS_POSITION-29 "None"
*MEAS_COND_AXIS_POSITION-30 "None"
*MEAS_COND_AXIS_POSITION-31 "PSA_open"
*MEAS_COND_AXIS_POSITION-32 "Soller_slit_5.0deg"
*MEAS_COND_AXIS_POSITION-33 "None"
*MEAS_COND_AXIS_POSITION-34 "Bent"
*MEAS_COND_AXIS_POSITION-35 "BBM"
*MEAS_COND_AXIS_POSITION-36 "9.9900000000"
*MEAS_COND_AXIS_POSITION-37 "None"
*MEAS_COND_AXIS_POSITION-38 "618.5000000000"
*MEAS_COND_AXIS_POSITION-39 "550.0000000000"
*MEAS_COND_AXIS_UNIT-0 "deg"
*MEAS_COND_AXIS_UNIT-1 "deg"
*MEAS_COND_AXIS_UNIT-2 "deg"
*MEAS_COND_AXIS_UNIT-3 "deg"
*MEAS_COND_AXIS_UNIT-4 "deg"
*MEAS_COND_AXIS_UNIT-5 "deg"
*MEAS_COND_AXIS_UNIT-6 "deg"
*MEAS_COND_AXIS_UNIT-7 "deg"
*MEAS_COND_AXIS_UNIT-8 "deg"
*MEAS_COND_AXIS_UNIT-9 "deg"
*MEAS_COND_AXIS_UNIT-10 "mm"
*MEAS_COND_AXIS_UNIT-11 "mm"
*MEAS_COND_AXIS_UNIT-12 ""
*MEAS_COND_AXIS_UNIT-13 "deg"
*MEAS_COND_AXIS_UNIT-14 "deg"
*MEAS_COND_AXIS_UNIT-15 "mm"
*MEAS_COND_AXIS_UNIT-16 "pulse"
*MEAS_COND_AXIS_UNIT-17 ""
*MEAS_COND_AXIS_UNIT-18 "mm"
*MEAS_COND_AXIS_UNIT-19 "mm"
*MEAS_COND_AXIS_UNIT-20 ""
*MEAS_COND_AXIS_UNIT-21 "mm"
*MEAS_COND_AXIS_UNIT-22 ""
*MEAS_COND_AXIS_UNIT-23 "mm"
*MEAS_COND_AXIS_UNIT-24 "mm"
*MEAS_COND_AXIS_UNIT-25 ""
*MEAS_COND_AXIS_UNIT-26 ""
*MEAS_COND_AXIS_UNIT-27 ""
*MEAS_COND_AXIS_UNIT-28 ""
*MEAS_COND_AXIS_UNIT-29 ""
*MEAS_COND_AXIS_UNIT-30 ""
*MEAS_COND_AXIS_UNIT-31 ""
*MEAS_COND_AXIS_UNIT-32 ""
*MEAS_COND_AXIS_UNIT-33 ""
*MEAS_COND_AXIS_UNIT-34 ""
*MEAS_COND_AXIS_UNIT-35 ""
*MEAS_COND_AXIS_UNIT-36 "deg"
*MEAS_COND_AXIS_UNIT-37 ""
*MEAS_COND_AXIS_UNIT-38 "V"
*MEAS_COND_AXIS_UNIT-39 "mV"
*MEAS_COND_COUNTER_CNTLOSS_CORR "1.0000000000"
*MEAS_COND_COUNTER_PHABASE "550.0000000000"
*MEAS_COND_COUNTER_PHAWINDOW "878.7500000000"
*MEAS_COND_COUNTER_PHA_UNIT "mV"
*MEAS_COND_COUNTER_TAUDIFF "0.2230000000"
*MEAS_COND_COUNTER_TAUINT "0.7199000000"
*MEAS_COND_IRRADIATION_MODE "OFF"
*MEAS_COND_IRRADIATION_WIDTH ""
*MEAS_COND_OPT_ATTR "Bragg-Brentano focusing"
*MEAS_COND_OPT_NAME "@BB focusing"
*MEAS_COND_UNSYMMETRIC_MODE "OFF"
*MEAS_COND_XG_CURRENT "150.0000000000"
*MEAS_COND_XG_VOLTAGE "40.0000000000"
*MEAS_COND_XG_WAVE_TYPE "Ka"
*MEAS_DATA_COUNT "4001.0000000000"
*MEAS_SCAN_AXIS_X "Theta/2-Theta"
*MEAS_SCAN_AXIS_X_INTERNAL "TwoThetaTheta"
*MEAS_SCAN_END_TIME "05/17/17 10:54:04"
*MEAS_SCAN_MODE "CONTINUOUS"
*MEAS_SCAN_MONITOR "0"
*MEAS_SCAN_RESOLUTION_X "0.0002"
*MEAS_SCAN_SPEED "6.0"
*MEAS_SCAN_SPEED_UNIT "deg/min"
*MEAS_SCAN_START "10.0000000000"
*MEAS_SCAN_START_TIME "05/17/17 10:40:18"
*MEAS_SCAN_STEP "0.0200000000"
*MEAS_SCAN_STOP "90.0000000000"
*MEAS_SCAN_UNIT_X "deg"
*MEAS_SCAN_UNIT_Y "counts"
*RAS_HEADER_END
*RAS_INT_START
10.0000 33.0000 1.0000
10.0600 45.0000 1.0000
10.1200 46.0000 1.0000
10.1800 46.0000 1.0000
10.2400 38.0000 1.0000
10.3000 37.0000 1.0000
10.3600 37.0000 1.0000
10.4200 52.0000 1.0000
10.4800 42.0000 1.0000
10.5400 46.0000 1.0000
10.6000 35.0000 1.0000
10.6600 41.0000 1.0000
10.7200 30.0000 1.0000
10.7800 55.0000 1.0000
10.8400 36.0000 1.0000
10.9000 45.0000 1.0000
10.9600 44.0000 1.0000
11.0200 44.0000 1.0000
11.0800 55.0000 1.0000
11.1400 39.0000 1.0000
11.2000 41.0000 1.0000
11.2600 45.0000 1.0000
11.3200 42.0000 1.0000
11.3800 45.0000 1.0000
11.4400 54.0000 1.0000
11.5000 43.0000 1.0000
11.5600 44.0000 1.0000
11.6200 47.0000 1.0000
11.6800 33.0000 1.0000
11.7400 42.0000 1.0000
11.8000 35.0000 1.0000
11.8600 39.0000 1.0000
11.9200 43.0000 1.0000
11.9800 43.0000 1.0000
12.0400 39.0000 1.0000
12.1000 43.0000 1.0000
12.1600 41.0000 1.0000
12.2200 38.0000 1.0000
12.2800 47.0000 1.0000
12.3400 40.0000 1.0000
12.4000 40.0000 1.0000
12.4600 49.0000 1.0000
12.5200 42.0000 1.0000
12.5800 34.0000 1.0000
12.6400 29.0000 1.0000
12.7000 45.0000 1.0000
12.7600 43.0000 1.0000
12.8200 24.0000 1.0000
12.8800 25.0000 1.0000
12.9400 42.0000 1.0000
13.0000 47.0000 1.0000
13.0600 49.0000 1.0000
13.1200 34.0000 1.0000
13.1800 37.0000 1.0000
13.2400 46.0000 1.0000
13.3000 37.0000 1.0000
13.3600 46.0000 1.0000
13.4200 43.0000 1.0000
13.4800 41.0000 1.0000
13.5400 35.0000 1.0000
13.6000 44.0000 1.0000
13.6600 35.0000 1.0000
13.7200 50.0000 1.0000
13.7800 50.0000 1.0000
13.8400 39.0000 1.0000
13.9000 40.0000 1.0000
13.9600 37.0000 1.0000
14.0200 31.0000 1.0000
14.0800 40.0000 1.0000
14.1400 31.0000 1.0000
14.2000 40.0000 1.0000
14.2600 45.0000 1.0000
14.3200 45.0000 1.0000
14.3800 43.0000 1.0000
14.4400 41.0000 1.0000
14.5000 37.0000 1.0000
14.5600 37.0000 1.0000
14.6200 47.0000 1.0000
14.6800 30.0000 1.0000
14.7400 35.0000 1.0000
14.8000 36.0000 1.0000
14.8600 34.0000 1.0000
14.9200 38.0000 1.0000
14.9800 31.0000 1.0000
15.0400 27.0000 1.0000
15.1000 32.0000 1.0000
15.1600 33.0000 1.0000
15.2200 29.0000 1.0000
15.2800 33.0000 1.0000
15.3400 37.0000 1.0000
15.4000 33.0000 1.0000
15.4600 35.0000 1.0000
15.5200 26.0000 1.0000
15.5800 36.0000 1.0000
15.6400 38.0000 1.0000
15.7000 35.0000 1.0000
15.7600 34.0000 1.0000
15.8200 46.0000 1.0000
15.8800 31.0000 1.0000
15.9400 35.0000 1.0000
16.0000 33.0000 1.0000
16.0600 23.0000 1.0000
16.1200 39.0000 1.0000
16.1800 26.0000 1.0000
16.2400 27.0000 1.0000
16.3000 35.0000 1.0000
16.3600 33.0000 1.0000
16.4200 30.0000 1.0000
16.4800 38.0000 1.0000
16.5400 36.0000 1.0000
16.6000 34.0000 1.0000
16.6600 23.0000 1.0000
16.7200 23.0000 1.0000
16.7800 24.0000 1.0000
16.8400 25.0000 1.0000
16.9000 40.0000 1.0000
16.9600 32.0000 1.0000
17.0200 33.0000 1.0000
17.0800 48.0000 1.0000
17.1400 36.0000 1.0000
17.2000 29.0000 1.0000
17.2600 31.0000 1.0000
17.3200 28.0000 1.0000
17.3800 27.0000 1.0000
17.4400 28.0000 1.0000
17.5000 34.0000 1.0000
17.5600 25.0000 1.0000
17.6200 23.0000 1.0000
17.6800 26.0000 1.0000
17.7400 30.0000 1.0000
17.8000 31.0000 1.0000
17.8600 33.0000 1.0000
17.9200 30.0000 1.0000
17.9800 35.0000 1.0000
18.0400 33.0000 1.0000
18.1000 32.0000 1.0000
18.1600 25.0000 1.0000
18.2200 28.0000 1.0000
18.2800 18.0000 1.0000
18.3400 37.0000 1.0000
18.4000 23.0000 1.0000
18.4600 35.0000 1.0000
18.5200 32.0000 1.0000
18.5800 30.0000 1.0000
18.6400 33.0000 1.0000
18.7000 32.0000 1.0000
18.7600 26.0000 1.0000
18.8200 23.0000 1.0000
18.8800 23.0000 1.0000
18.9400 25.0000 1.0000
19.0000 21.0000 1.0000
19.0600 19.0000 1.0000
19.1200 28.0000 1.0000
19.1800 30.0000 1.0000
19.2400 28.0000 1.0000
19.3000 30.0000 1.0000
19.3600 29.0000 1.0000
19.4200 27.0000 1.0000
19.4800 37.0000 1.0000
19.5400 28.0000 1.0000
19.6000 28.0000 1.0000
19.6600 29.0000 1.0000
19.7200 27.0000 1.0000
19.7800 22.0000 1.0000
19.8400 24.0000 1.0000
19.9000 29.0000 1.0000
19.9600 29.0000 1.0000
20.0200 20.0000 1.0000
20.0800 25.0000 1.0000
20.1400 34.0000 1.0000
20.2000 24.0000 1.0000
20.2600 22.0000 1.0000
20.3200 13.0000 1.0000
20.3800 25.0000 1.0000
20.4400 18.0000 1.0000
20.5000 29.0000 1.0000
20.5600 22.0000 1.0000
20.6200 21.0000 1.0000
20.6800 22.0000 1.0000
20.7400 15.0000 1.0000
20.8000 24.0000 1.0000
20.8600 18.0000 1.0000
20.9200 20.0000 1.0000
20.9800 13.0000 1.0000
21.0400 21.0000 1.0000
21.1000 21.0000 1.0000
21.1600 14.0000 1.0000
21.2200 19.0000 1.0000
21.2800 18.0000 1.0000
21.3400 27.0000 1.0000
21.4000 18.0000 1.0000
21.4600 23.0000 1.0000
21.5200 17.0000 1.0000
21.5800 21.0000 1.0000
21.6400 17.0000 1.0000
21.7000 14.0000 1.0000
21.7600 18.0000 1.0000
21.8200 15.0000 1.0000
21.8800 16.0000 1.0000
21.9400 17.0000 1.0000
22.0000 21.0000 1.0000
22.0600 18.0000 1.0000
22.1200 21.0000 1.0000
22.1800 24.0000 1.0000
22.2400 19.0000 1.0000
22.3000 12.0000 1.0000
22.3600 12.0000 1.0000
22.4200 20.0000 1.0000
22.4800 16.0000 1.0000
22.5400 14.0000 1.0000
22.6000 22.0000 1.0000
22.6600 29.0000 1.0000
22.7200 20.0000 1.0000
22.7800 27.0000 1.0000
22.8400 15.0000 1.0000
22.9000 25.0000 1.0000
22.9600 16.0000 1.0000
23.0200 10.0000 1.0000
23.0800 20.0000 1.0000
23.1400 18.0000 1.0000
23.2000 13.0000 1.0000
23.2600 26.0000 1.0000
23.3200 16.0000 1.0000
23.3800 20.0000 1.0000
23.4400 23.0000 1.0000
23.5000 12.0000 1.0000
23.5600 22.0000 1.0000
23.6200 13.0000 1.0000
23.6800 15.0000 1.0000
23.7400 17.0000 1.0000
23.8000 17.0000 1.0000
23.8600 21.0000 1.0000
23.9200 16.0000 1.0000
23.9800 23.0000 1.0000
24.0400 18.0000 1.0000
24.1000 22.0000 1.0000
24.1600 12.0000 1.0000
24.2200 18.0000 1.0000
24.2800 16.0000 1.0000
24.3400 13.0000 1.0000
24.4000 18.0000 1.0000
24.4600 13.0000 1.0000
24.5200 13.0000 1.0000
24.5800 15.0000 1.0000
24.6400 18.0000 1.0000
24.7000 10.0000 1.0000
24.7600 17.0000 1.0000
24.8200 14.0000 1.0000
24.8800 18.0000 1.0000
24.9400 13.0000 1.0000
25.0000 8.0000 1.0000
25.0600 8.0000 1.0000
25.1200 13.0000 1.0000
25.1800 13.0000 1.0000
25.2400 11.0000 1.0000
25.3000 13.0000 1.0000
25.3600 10.0000 1.0000
25.4200 10.0000 1.0000
25.4800 15.0000 1.0000
25.5400 12.0000 1.0000
25.6000 14.0000 1.0000
25.6600 19.0000 1.0000
25.7200 15.0000 1.0000
25.7800 15.0000 1.0000
25.8400 13.0000 1.0000
25.9000 17.0000 1.0000
25.9600 18.0000 1.0000
26.0200 12.0000 1.0000
26.0800 14.0000 1.0000
26.1400 10.0000 1.0000
26.2000 6.0000 1.0000
26.2600 8.0000 1.0000
26.3200 12.0000 1.0000
26.3800 14.0000 1.0000
26.4400 14.0000 1.0000
26.5000 9.0000 1.0000
26.5600 14.0000 1.0000
26.6200 16.0000 1.0000
26.6800 14.0000 1.0000
26.7400 13.0000 1.0000
26.8000 16.0000 1.0000
26.8600 10.0000 1.0000
26.9200 8.0000 1.0000
26.9800 11.0000 1.0000
27.0400 15.0000 1.0000
27.1000 5.0000 1.0000
27.1600 12.0000 1.0000
27.2200 9.0000 1.0000
27.2800 10.0000 1.0000
27.3400 9.0000 1.0000
27.4000 14.0000 1.0000
27.4600 13.0000 1.0000
27.5200 10.0000 1.0000
27.5800 16.0000 1.0000
27.6400 13.0000 1.0000
27.7000 10.0000 1.0000
27.7600 13.0000 1.0000
27.8200 12.0000 1.0000
27.8800 12.0000 1.0000
27.9400 7.0000 1.0000
28.0000 16.0000 1.0000
28.0600 13.0000 1.0000
28.1200 14.0000 1.0000
28.1800 9.0000 1.0000
28.2400 9.0000 1.0000
28.3000 11.0000 1.0000
28.3600 14.0000 1.0000
28.4200 8.0000 1.0000
28.4800 7.0000 1.0000
28.5400 7.0000 1.0000
28.6000 10.0000 1.0000
28.6600 6.0000 1.0000
28.7200 14.0000 1.0000
28.7800 11.0000 1.0000
28.8400 10.0000 1.0000
28.9000 8.0000 1.0000
28.9600 7.0000 1.0000
29.0200 4.0000 1.0000
29.0800 16.0000 1.0000
29.1400 6.0000 1.0000
29.2000 12.0000 1.0000
29.2600 15.0000 1.0000
29.3200 10.0000 1.0000
29.3800 10.0000 1.0000
29.4400 11.0000 1.0000
29.5000 8.0000 1.0000
29.5600 11.0000 1.0000
29.6200 10.0000 1.0000
29.6800 12.0000 1.0000
29.7400 8.0000 1.0000
29.8000 7.0000 1.0000
29.8600 9.0000 1.0000
29.9200 14.0000 1.0000
29.9800 7.0000 1.0000
30.0400 10.0000 1.0000
30.1000 16.0000 1.0000
30.1600 4.0000 1.0000
30.2200 13.0000 1.0000
30.2800 8.0000 1.0000
30.3400 3.0000 1.0000
30.4000 10.0000 1.0000
30.4600 8.0000 1.0000
30.5200 8.0000 1.0000
30.5800 9.0000 1.0000
30.6400 7.0000 1.0000
30.7000 9.0000 1.0000
30.7600 12.0000 1.0000
30.8200 12.0000 1.0000
30.8800 8.0000 1.0000
30.9400 8.0000 1.0000
31.0000 7.0000 1.0000
31.0600 15.0000 1.0000
31.1200 11.0000 1.0000
31.1800 9.0000 1.0000
31.2400 8.0000 1.0000
31.3000 5.0000 1.0000
31.3600 9.0000 1.0000
31.4200 8.0000 1.0000
31.4800 9.0000 1.0000
31.5400 15.0000 1.0000
31.6000 9.0000 1.0000
31.6600 15.0000 1.0000
31.7200 13.0000 1.0000
31.7800 9.0000 1.0000
31.8400 10.0000 1.0000
31.9000 13.0000 1.0000
31.9600 6.0000 1.0000
32.0200 12.0000 1.0000
32.0800 15.0000 1.0000
32.1400 17.0000 1.0000
32.2000 12.0000 1.0000
32.2600 19.0000 1.0000
32.3200 28.0000 1.0000
32.3800 25.0000 1.0000
32.4400 27.0000 1.0000
32.5000 27.0000 1.0000
32.5600 38.0000 1.0000
32.6200 47.0000 1.0000
32.6800 53.0000 1.0000
32.7400 58.0000 1.0000
32.8000 56.0000 1.0000
32.8600 73.0000 1.0000
32.9200 85.0000 1.0000
32.9800 91.0000 1.0000
33.0400 108.0000 1.0000
33.1000 106.0000 1.0000
33.1600 121.0000 1.0000
33.2200 101.0000 1.0000
33.2800 102.0000 1.0000
33.3400 113.0000 1.0000
33.4000 124.0000 1.0000
33.4600 115.0000 1.0000
33.5200 114.0000 1.0000
33.5800 129.0000 1.0000
33.6400 133.0000 1.0000
33.7000 123.0000 1.0000
33.7600 104.0000 1.0000
33.8200 105.0000 1.0000
33.8800 89.0000 1.0000
33.9400 104.0000 1.0000
34.0000 108.0000 1.0000
34.0600 84.0000 1.0000
34.1200 92.0000 1.0000
34.1800 94.0000 1.0000
34.2400 67.0000 1.0000
34.3000 92.0000 1.0000
34.3600 100.0000 1.0000
34.4200 85.0000 1.0000
34.4800 88.0000 1.0000
34.5400 83.0000 1.0000
34.6000 76.0000 1.0000
34.6600 80.0000 1.0000
34.7200 79.0000 1.0000
34.7800 83.0000 1.0000
34.8400 75.0000 1.0000
34.9000 79.0000 1.0000
34.9600 52.0000 1.0000
35.0200 65.0000 1.0000
35.0800 60.0000 1.0000
35.1400 63.0000 1.0000
35.2000 74.0000 1.0000
35.2600 57.0000 1.0000
35.3200 57.0000 1.0000
35.3800 60.0000 1.0000
35.4400 51.0000 1.0000
35.5000 53.0000 1.0000
35.5600 46.0000 1.0000
35.6200 44.0000 1.0000
35.6800 45.0000 1.0000
35.7400 46.0000 1.0000
35.8000 47.0000 1.0000
35.8600 34.0000 1.0000
35.9200 35.0000 1.0000
35.9800 39.0000 1.0000
36.0400 34.0000 1.0000
36.1000 38.0000 1.0000
36.1600 42.0000 1.0000
36.2200 59.0000 1.0000
36.2800 62.0000 1.0000
36.3400 88.0000 1.0000
36.4000 104.0000 1.0000
36.4600 130.0000 1.0000
36.5200 142.0000 1.0000
36.5800 132.0000 1.0000
36.6400 103.0000 1.0000
36.7000 43.0000 1.0000
36.7600 33.0000 1.0000
36.8200 28.0000 1.0000
36.8800 19.0000 1.0000
36.9400 19.0000 1.0000
37.0000 12.0000 1.0000
37.0600 18.0000 1.0000
37.1200 10.0000 1.0000
37.1800 15.0000 1.0000
37.2400 13.0000 1.0000
37.3000 7.0000 1.0000
37.3600 9.0000 1.0000
37.4200 5.0000 1.0000
37.4800 11.0000 1.0000
37.5400 10.0000 1.0000
37.6000 9.0000 1.0000
37.6600 9.0000 1.0000
37.7200 7.0000 1.0000
37.7800 6.0000 1.0000
37.8400 9.0000 1.0000
37.9000 10.0000 1.0000
37.9600 4.0000 1.0000
38.0200 7.0000 1.0000
38.0800 9.0000 1.0000
38.1400 8.0000 1.0000
38.2000 9.0000 1.0000
38.2600 8.0000 1.0000
38.3200 8.0000 1.0000
38.3800 5.0000 1.0000
38.4400 7.0000 1.0000
38.5000 9.0000 1.0000
38.5600 7.0000 1.0000
38.6200 8.0000 1.0000
38.6800 11.0000 1.0000
38.7400 5.0000 1.0000
38.8000 6.0000 1.0000
38.8600 3.0000 1.0000
38.9200 5.0000 1.0000
38.9800 6.0000 1.0000
39.0400 8.0000 1.0000
39.1000 9.0000 1.0000
39.1600 8.0000 1.0000
39.2200 5.0000 1.0000
39.2800 9.0000 1.0000
39.3400 9.0000 1.0000
39.4000 7.0000 1.0000
39.4600 3.0000 1.0000
39.5200 7.0000 1.0000
39.5800 4.0000 1.0000
39.6400 3.0000 1.0000
39.7000 5.0000 1.0000
39.7600 12.0000 1.0000
39.8200 4.0000 1.0000
39.8800 5.0000 1.0000
39.9400 10.0000 1.0000
40.0000 5.0000 1.0000
40.0600 5.0000 1.0000
40.1200 5.0000 1.0000
40.1800 5.0000 1.0000
40.2400 13.0000 1.0000
40.3000 8.0000 1.0000
40.3600 11.0000 1.0000
40.4200 11.0000 1.0000
40.4800 3.0000 1.0000
40.5400 11.0000 1.0000
40.6000 5.0000 1.0000
40.6600 12.0000 1.0000
40.7200 13.0000 1.0000
40.7800 9.0000 1.0000
40.8400 13.0000 1.0000
40.9000 8.0000 1.0000
40.9600 8.0000 1.0000
41.0200 9.0000 1.0000
41.0800 11.0000 1.0000
41.1400 10.0000 1.0000
41.2000 4.0000 1.0000
41.2600 9.0000 1.0000
41.3200 7.0000 1.0000
41.3800 4.0000 1.0000
41.4400 8.0000 1.0000
41.5000 6.0000 1.0000
41.5600 7.0000 1.0000
41.6200 8.0000 1.0000
41.6800 4.0000 1.0000
41.7400 8.0000 1.0000
41.8000 10.0000 1.0000
41.8600 7.0000 1.0000
41.9200 5.0000 1.0000
41.9800 13.0000 1.0000
42.0400 11.0000 1.0000
42.1000 5.0000 1.0000
42.1600 8.0000 1.0000
42.2200 6.0000 1.0000
42.2800 7.0000 1.0000
42.3400 9.0000 1.0000
42.4000 5.0000 1.0000
42.4600 12.0000 1.0000
42.5200 10.0000 1.0000
42.5800 4.0000 1.0000
42.6400 10.0000 1.0000
42.7000 15.0000 1.0000
42.7600 8.0000 1.0000
42.8200 12.0000 1.0000
42.8800 7.0000 1.0000
42.9400 9.0000 1.0000
43.0000 7.0000 1.0000
43.0600 7.0000 1.0000
43.1200 10.0000 1.0000
43.1800 6.0000 1.0000
43.2400 5.0000 1.0000
43.3000 3.0000 1.0000
43.3600 6.0000 1.0000
43.4200 8.0000 1.0000
43.4800 9.0000 1.0000
43.5400 8.0000 1.0000
43.6000 9.0000 1.0000
43.6600 6.0000 1.0000
43.7200 4.0000 1.0000
43.7800 7.0000 1.0000
43.8400 6.0000 1.0000
43.9000 4.0000 1.0000
43.9600 9.0000 1.0000
44.0200 4.0000 1.0000
44.0800 7.0000 1.0000
44.1400 2.0000 1.0000
44.2000 7.0000 1.0000
44.2600 5.0000 1.0000
44.3200 8.0000 1.0000
44.3800 6.0000 1.0000
44.4400 5.0000 1.0000
44.5000 7.0000 1.0000
44.5600 10.0000 1.0000
44.6200 9.0000 1.0000
44.6800 13.0000 1.0000
44.7400 3.0000 1.0000
44.8000 7.0000 1.0000
44.8600 7.0000 1.0000
44.9200 10.0000 1.0000
44.9800 5.0000 1.0000
45.0400 7.0000 1.0000
45.1000 8.0000 1.0000
45.1600 10.0000 1.0000
45.2200 5.0000 1.0000
45.2800 7.0000 1.0000
45.3400 6.0000 1.0000
45.4000 7.0000 1.0000
45.4600 7.0000 1.0000
45.5200 6.0000 1.0000
45.5800 3.0000 1.0000
45.6400 5.0000 1.0000
45.7000 10.0000 1.0000
45.7600 3.0000 1.0000
45.8200 7.0000 1.0000
45.8800 5.0000 1.0000
45.9400 3.0000 1.0000
46.0000 4.0000 1.0000
46.0600 4.0000 1.0000
46.1200 2.0000 1.0000
46.1800 5.0000 1.0000
46.2400 8.0000 1.0000
46.3000 9.0000 1.0000
46.3600 5.0000 1.0000
46.4200 2.0000 1.0000
46.4800 6.0000 1.0000
46.5400 6.0000 1.0000
46.6000 2.0000 1.0000
46.6600 5.0000 1.0000
46.7200 1.0000 1.0000
46.7800 4.0000 1.0000
46.8400 6.0000 1.0000
46.9000 7.0000 1.0000
46.9600 6.0000 1.0000
47.0200 5.0000 1.0000
47.0800 4.0000 1.0000
47.1400 7.0000 1.0000
47.2000 5.0000 1.0000
47.2600 6.0000 1.0000
47.3200 1.0000 1.0000
47.3800 6.0000 1.0000
47.4400 2.0000 1.0000
47.5000 8.0000 1.0000
47.5600 4.0000 1.0000
47.6200 7.0000 1.0000
47.6800 6.0000 1.0000
47.7400 5.0000 1.0000
47.8000 6.0000 1.0000
47.8600 7.0000 1.0000
47.9200 2.0000 1.0000
47.9800 6.0000 1.0000
48.0400 4.0000 1.0000
48.1000 4.0000 1.0000
48.1600 7.0000 1.0000
48.2200 14.0000 1.0000
48.2800 10.0000 1.0000
48.3400 6.0000 1.0000
48.4000 7.0000 1.0000
48.4600 3.0000 1.0000
48.5200 8.0000 1.0000
48.5800 7.0000 1.0000
48.6400 6.0000 1.0000
48.7000 5.0000 1.0000
48.7600 8.0000 1.0000
48.8200 3.0000 1.0000
48.8800 5.0000 1.0000
48.9400 3.0000 1.0000
49.0000 7.0000 1.0000
49.0600 4.0000 1.0000
49.1200 9.0000 1.0000
49.1800 6.0000 1.0000
49.2400 4.0000 1.0000
49.3000 4.0000 1.0000
49.3600 6.0000 1.0000
49.4200 13.0000 1.0000
49.4800 4.0000 1.0000
49.5400 6.0000 1.0000
49.6000 7.0000 1.0000
49.6600 8.0000 1.0000
49.7200 2.0000 1.0000
49.7800 2.0000 1.0000
49.8400 8.0000 1.0000
49.9000 6.0000 1.0000
49.9600 3.0000 1.0000
50.0200 6.0000 1.0000
50.0800 7.0000 1.0000
50.1400 2.0000 1.0000
50.2000 9.0000 1.0000
50.2600 1.0000 1.0000
50.3200 3.0000 1.0000
50.3800 8.0000 1.0000
50.4400 13.0000 1.0000
50.5000 8.0000 1.0000
50.5600 1.0000 1.0000
50.6200 7.0000 1.0000
50.6800 1.0000 1.0000
50.7400 8.0000 1.0000
50.8000 3.0000 1.0000
50.8600 7.0000 1.0000
50.9200 5.0000 1.0000
50.9800 2.0000 1.0000
51.0400 6.0000 1.0000
51.1000 4.0000 1.0000
51.1600 5.0000 1.0000
51.2200 5.0000 1.0000
51.2800 4.0000 1.0000
51.3400 4.0000 1.0000
51.4000 4.0000 1.0000
51.4600 9.0000 1.0000
51.5200 6.0000 1.0000
51.5800 7.0000 1.0000
51.6400 4.0000 1.0000
51.7000 8.0000 1.0000
51.7600 6.0000 1.0000
51.8200 7.0000 1.0000
51.8800 3.0000 1.0000
51.9400 4.0000 1.0000
52.0000 7.0000 1.0000
52.0600 9.0000 1.0000
52.1200 5.0000 1.0000
52.1800 1.0000 1.0000
52.2400 2.0000 1.0000
52.3000 5.0000 1.0000
52.3600 3.0000 1.0000
52.4200 5.0000 1.0000
52.4800 1.0000 1.0000
52.5400 3.0000 1.0000
52.6000 5.0000 1.0000
52.6600 4.0000 1.0000
52.7200 4.0000 1.0000
52.7800 12.0000 1.0000
52.8400 9.0000 1.0000
52.9000 6.0000 1.0000
52.9600 5.0000 1.0000
53.0200 8.0000 1.0000
53.0800 8.0000 1.0000
53.1400 6.0000 1.0000
53.2000 8.0000 1.0000
53.2600 6.0000 1.0000
53.3200 4.0000 1.0000
53.3800 4.0000 1.0000
53.4400 5.0000 1.0000
53.5000 13.0000 1.0000
53.5600 6.0000 1.0000
53.6200 5.0000 1.0000
53.6800 5.0000 1.0000
53.7400 9.0000 1.0000
53.8000 6.0000 1.0000
53.8600 8.0000 1.0000
53.9200 2.0000 1.0000
53.9800 7.0000 1.0000
54.0400 9.0000 1.0000
54.1000 1.0000 1.0000
54.1600 6.0000 1.0000
54.2200 7.0000 1.0000
54.2800 2.0000 1.0000
54.3400 9.0000 1.0000
54.4000 7.0000 1.0000
54.4600 4.0000 1.0000
54.5200 6.0000 1.0000
54.5800 6.0000 1.0000
54.6400 8.0000 1.0000
54.7000 8.0000 1.0000
54.7600 8.0000 1.0000
54.8200 11.0000 1.0000
54.8800 6.0000 1.0000
54.9400 3.0000 1.0000
55.0000 1.0000 1.0000
55.0600 8.0000 1.0000
55.1200 4.0000 1.0000
55.1800 3.0000 1.0000
55.2400 6.0000 1.0000
55.3000 8.0000 1.0000
55.3600 5.0000 1.0000
55.4200 4.0000 1.0000
55.4800 9.0000 1.0000
55.5400 7.0000 1.0000
55.6000 8.0000 1.0000
55.6600 6.0000 1.0000
55.7200 7.0000 1.0000
55.7800 9.0000 1.0000
55.8400 10.0000 1.0000
55.9000 10.0000 1.0000
55.9600 5.0000 1.0000
56.0200 5.0000 1.0000
56.0800 7.0000 1.0000
56.1400 4.0000 1.0000
56.2000 7.0000 1.0000
56.2600 2.0000 1.0000
56.3200 8.0000 1.0000
56.3800 3.0000 1.0000
56.4400 6.0000 1.0000
56.5000 9.0000 1.0000
56.5600 7.0000 1.0000
56.6200 7.0000 1.0000
56.6800 6.0000 1.0000
56.7400 9.0000 1.0000
56.8000 7.0000 1.0000
56.8600 6.0000 1.0000
56.9200 3.0000 1.0000
56.9800 10.0000 1.0000
57.0400 4.0000 1.0000
57.1000 8.0000 1.0000
57.1600 4.0000 1.0000
57.2200 8.0000 1.0000
57.2800 4.0000 1.0000
57.3400 11.0000 1.0000
57.4000 4.0000 1.0000
57.4600 5.0000 1.0000
57.5200 5.0000 1.0000
57.5800 6.0000 1.0000
57.6400 6.0000 1.0000
57.7000 7.0000 1.0000
57.7600 3.0000 1.0000
57.8200 10.0000 1.0000
57.8800 2.0000 1.0000
57.9400 7.0000 1.0000
58.0000 3.0000 1.0000
58.0600 5.0000 1.0000
58.1200 6.0000 1.0000
58.1800 5.0000 1.0000
58.2400 7.0000 1.0000
58.3000 5.0000 1.0000
58.3600 7.0000 1.0000
58.4200 11.0000 1.0000
58.4800 7.0000 1.0000
58.5400 4.0000 1.0000
58.6000 18.0000 1.0000
58.6600 8.0000 1.0000
58.7200 7.0000 1.0000
58.7800 3.0000 1.0000
58.8400 4.0000 1.0000
58.9000 9.0000 1.0000
58.9600 8.0000 1.0000
59.0200 5.0000 1.0000
59.0800 7.0000 1.0000
59.1400 9.0000 1.0000
59.2000 8.0000 1.0000
59.2600 10.0000 1.0000
59.3200 6.0000 1.0000
59.3800 8.0000 1.0000
59.4400 4.0000 1.0000
59.5000 10.0000 1.0000
59.5600 9.0000 1.0000
59.6200 8.0000 1.0000
59.6800 16.0000 1.0000
59.7400 9.0000 1.0000
59.8000 14.0000 1.0000
59.8600 7.0000 1.0000
59.9200 6.0000 1.0000
59.9800 11.0000 1.0000
60.0400 6.0000 1.0000
60.1000 8.0000 1.0000
60.1600 6.0000 1.0000
60.2200 7.0000 1.0000
60.2800 10.0000 1.0000
60.3400 12.0000 1.0000
60.4000 9.0000 1.0000
60.4600 14.0000 1.0000
60.5200 10.0000 1.0000
60.5800 11.0000 1.0000
60.6400 4.0000 1.0000
60.7000 12.0000 1.0000
60.7600 10.0000 1.0000
60.8200 9.0000 1.0000
60.8800 9.0000 1.0000
60.9400 4.0000 1.0000
61.0000 13.0000 1.0000
61.0600 14.0000 1.0000
61.1200 19.0000 1.0000
61.1800 9.0000 1.0000
61.2400 7.0000 1.0000
61.3000 16.0000 1.0000
61.3600 13.0000 1.0000
61.4200 7.0000 1.0000
61.4800 9.0000 1.0000
61.5400 19.0000 1.0000
61.6000 11.0000 1.0000
61.6600 19.0000 1.0000
61.7200 48.0000 1.0000
61.7800 21.0000 1.0000
61.8400 10.0000 1.0000
61.9000 18.0000 1.0000
61.9600 10.0000 1.0000
62.0200 19.0000 1.0000
62.0800 18.0000 1.0000
62.1400 12.0000 1.0000
62.2000 12.0000 1.0000
62.2600 13.0000 1.0000
62.3200 8.0000 1.0000
62.3800 10.0000 1.0000
62.4400 8.0000 1.0000
62.5000 10.0000 1.0000
62.5600 17.0000 1.0000
62.6200 11.0000 1.0000
62.6800 9.0000 1.0000
62.7400 18.0000 1.0000
62.8000 14.0000 1.0000
62.8600 6.0000 1.0000
62.9200 8.0000 1.0000
62.9800 16.0000 1.0000
63.0400 13.0000 1.0000
63.1000 14.0000 1.0000
63.1600 17.0000 1.0000
63.2200 17.0000 1.0000
63.2800 9.0000 1.0000
63.3400 13.0000 1.0000
63.4000 8.0000 1.0000
63.4600 10.0000 1.0000
63.5200 14.0000 1.0000
63.5800 11.0000 1.0000
63.6400 11.0000 1.0000
63.7000 12.0000 1.0000
63.7600 19.0000 1.0000
63.8200 16.0000 1.0000
63.8800 10.0000 1.0000
63.9400 13.0000 1.0000
64.0000 14.0000 1.0000
64.0600 16.0000 1.0000
64.1200 19.0000 1.0000
64.1800 11.0000 1.0000
64.2400 23.0000 1.0000
64.3000 12.0000 1.0000
64.3600 14.0000 1.0000
64.4200 17.0000 1.0000
64.4800 12.0000 1.0000
64.5400 16.0000 1.0000
64.6000 14.0000 1.0000
64.6600 21.0000 1.0000
64.7200 11.0000 1.0000
64.7800 16.0000 1.0000
64.8400 17.0000 1.0000
64.9000 24.0000 1.0000
64.9600 17.0000 1.0000
65.0200 25.0000 1.0000
65.0800 21.0000 1.0000
65.1400 30.0000 1.0000
65.2000 24.0000 1.0000
65.2600 11.0000 1.0000
65.3200 26.0000 1.0000
65.3800 25.0000 1.0000
65.4400 31.0000 1.0000
65.5000 20.0000 1.0000
65.5600 27.0000 1.0000
65.6200 24.0000 1.0000
65.6800 23.0000 1.0000
65.7400 24.0000 1.0000
65.8000 28.0000 1.0000
65.8600 32.0000 1.0000
65.9200 45.0000 1.0000
65.9800 28.0000 1.0000
66.0400 32.0000 1.0000
66.1000 35.0000 1.0000
66.1600 34.0000 1.0000
66.2200 37.0000 1.0000
66.2800 32.0000 1.0000
66.3400 38.0000 1.0000
66.4000 44.0000 1.0000
66.4600 61.0000 1.0000
66.5200 65.0000 1.0000
66.5800 57.0000 1.0000
66.6400 41.0000 1.0000
66.7000 62.0000 1.0000
66.7600 52.0000 1.0000
66.8200 72.0000 1.0000
66.8800 101.0000 1.0000
66.9400 123.0000 1.0000
67.0000 121.0000 1.0000
67.0600 153.0000 1.0000
67.1200 146.0000 1.0000
67.1800 190.0000 1.0000
67.2400 220.0000 1.0000
67.3000 225.0000 1.0000
67.3600 241.0000 1.0000
67.4200 292.0000 1.0000
67.4800 319.0000 1.0000
67.5400 318.0000 1.0000
67.6000 389.0000 1.0000
67.6600 450.0000 1.0000
67.7200 463.0000 1.0000
67.7800 448.0000 1.0000
67.8400 524.0000 1.0000
67.9000 545.0000 1.0000
67.9600 634.0000 1.0000
68.0200 648.0000 1.0000
68.0800 698.0000 1.0000
68.1400 737.0000 1.0000
68.2000 780.0000 1.0000
68.2600 964.0000 1.0000
68.3200 999.0000 1.0000
68.3800 1093.0000 1.0000
68.4400 1217.0000 1.0000
68.5000 1399.0000 1.0000
68.5600 1597.0000 1.0000
68.6200 1912.0000 1.0000
68.6800 2396.0000 1.0000
68.7400 3467.0000 1.0000
68.8000 6185.0000 1.0000
68.8600 7744.0000 1.0000
68.9200 7637.0000 1.0000
68.9800 10385.0000 1.0000
69.0400 20755.0000 1.0000
69.1000 79498.0000 1.0000
69.1600 12333.0000 58.0358
69.2200 5144.0000 58.0358
69.2800 961.0000 58.0358
69.3400 3925.0000 58.0358
69.4000 4571.0005 58.0358
69.4600 605.0000 58.0358
69.5200 12200.0000 1.0000
69.5800 7272.0000 1.0000
69.6400 5039.0000 1.0000
69.7000 3790.0000 1.0000
69.7600 3047.0000 1.0000
69.8200 2377.0000 1.0000
69.8800 2070.0000 1.0000
69.9400 1774.0000 1.0000
70.0000 1606.0000 1.0000
70.0600 1355.0000 1.0000
70.1200 1186.0000 1.0000
70.1800 1119.0000 1.0000
70.2400 979.0000 1.0000
70.3000 880.0000 1.0000
70.3600 765.0000 1.0000
70.4200 703.0000 1.0000
70.4800 602.0000 1.0000
70.5400 484.0000 1.0000
70.6000 466.0000 1.0000
70.6600 391.0000 1.0000
70.7200 371.0000 1.0000
70.7800 330.0000 1.0000
70.8400 263.0000 1.0000
70.9000 236.0000 1.0000
70.9600 231.0000 1.0000
71.0200 204.0000 1.0000
71.0800 172.0000 1.0000
71.1400 182.0000 1.0000
71.2000 157.0000 1.0000
71.2600 141.0000 1.0000
71.3200 133.0000 1.0000
71.3800 114.0000 1.0000
71.4400 108.0000 1.0000
71.5000 127.0000 1.0000
71.5600 100.0000 1.0000
71.6200 89.0000 1.0000
71.6800 72.0000 1.0000
71.7400 88.0000 1.0000
71.8000 78.0000 1.0000
71.8600 79.0000 1.0000
71.9200 61.0000 1.0000
71.9800 72.0000 1.0000
72.0400 64.0000 1.0000
72.1000 64.0000 1.0000
72.1600 64.0000 1.0000
72.2200 53.0000 1.0000
72.2800 59.0000 1.0000
72.3400 45.0000 1.0000
72.4000 60.0000 1.0000
72.4600 57.0000 1.0000
72.5200 62.0000 1.0000
72.5800 46.0000 1.0000
72.6400 44.0000 1.0000
72.7000 52.0000 1.0000
72.7600 41.0000 1.0000
72.8200 37.0000 1.0000
72.8800 47.0000 1.0000
72.9400 34.0000 1.0000
73.0000 36.0000 1.0000
73.0600 34.0000 1.0000
73.1200 33.0000 1.0000
73.1800 36.0000 1.0000
73.2400 29.0000 1.0000
73.3000 30.0000 1.0000
73.3600 35.0000 1.0000
73.4200 30.0000 1.0000
73.4800 31.0000 1.0000
73.5400 24.0000 1.0000
73.6000 25.0000 1.0000
73.6600 32.0000 1.0000
73.7200 28.0000 1.0000
73.7800 31.0000 1.0000
73.8400 28.0000 1.0000
73.9000 18.0000 1.0000
73.9600 21.0000 1.0000
74.0200 30.0000 1.0000
74.0800 27.0000 1.0000
74.1400 21.0000 1.0000
74.2000 23.0000 1.0000
74.2600 29.0000 1.0000
74.3200 25.0000 1.0000
74.3800 15.0000 1.0000
74.4400 25.0000 1.0000
74.5000 24.0000 1.0000
74.5600 24.0000 1.0000
74.6200 22.0000 1.0000
74.6800 16.0000 1.0000
74.7400 23.0000 1.0000
74.8000 16.0000 1.0000
74.8600 21.0000 1.0000
74.9200 20.0000 1.0000
74.9800 13.0000 1.0000
75.0400 23.0000 1.0000
75.1000 15.0000 1.0000
75.1600 16.0000 1.0000
75.2200 20.0000 1.0000
75.2800 18.0000 1.0000
75.3400 12.0000 1.0000
75.4000 21.0000 1.0000
75.4600 15.0000 1.0000
75.5200 19.0000 1.0000
75.5800 11.0000 1.0000
75.6400 13.0000 1.0000
75.7000 20.0000 1.0000
75.7600 13.0000 1.0000
75.8200 13.0000 1.0000
75.8800 16.0000 1.0000
75.9400 13.0000 1.0000
76.0000 11.0000 1.0000
76.0600 9.0000 1.0000
76.1200 9.0000 1.0000
76.1800 11.0000 1.0000
76.2400 12.0000 1.0000
76.3000 12.0000 1.0000
76.3600 14.0000 1.0000
76.4200 11.0000 1.0000
76.4800 16.0000 1.0000
76.5400 10.0000 1.0000
76.6000 14.0000 1.0000
76.6600 12.0000 1.0000
76.7200 11.0000 1.0000
76.7800 9.0000 1.0000
76.8400 11.0000 1.0000
76.9000 15.0000 1.0000
76.9600 18.0000 1.0000
77.0200 16.0000 1.0000
77.0800 5.0000 1.0000
77.1400 16.0000 1.0000
77.2000 16.0000 1.0000
77.2600 10.0000 1.0000
77.3200 13.0000 1.0000
77.3800 17.0000 1.0000
77.4400 12.0000 1.0000
77.5000 15.0000 1.0000
77.5600 19.0000 1.0000
77.6200 18.0000 1.0000
77.6800 18.0000 1.0000
77.7400 19.0000 1.0000
77.8000 17.0000 1.0000
77.8600 14.0000 1.0000
77.9200 10.0000 1.0000
77.9800 13.0000 1.0000
78.0400 8.0000 1.0000
78.1000 16.0000 1.0000
78.1600 7.0000 1.0000
78.2200 7.0000 1.0000
78.2800 12.0000 1.0000
78.3400 10.0000 1.0000
78.4000 9.0000 1.0000
78.4600 3.0000 1.0000
78.5200 1.0000 1.0000
78.5800 5.0000 1.0000
78.6400 7.0000 1.0000
78.7000 13.0000 1.0000
78.7600 8.0000 1.0000
78.8200 6.0000 1.0000
78.8800 4.0000 1.0000
78.9400 5.0000 1.0000
79.0000 9.0000 1.0000
79.0600 8.0000 1.0000
79.1200 7.0000 1.0000
79.1800 9.0000 1.0000
79.2400 1.0000 1.0000
79.3000 9.0000 1.0000
79.3600 5.0000 1.0000
79.4200 5.0000 1.0000
79.4800 1.0000 1.0000
79.5400 6.0000 1.0000
79.6000 3.0000 1.0000
79.6600 4.0000 1.0000
79.7200 5.0000 1.0000
79.7800 1.0000 1.0000
79.8400 9.0000 1.0000
79.9000 6.0000 1.0000
79.9600 6.0000 1.0000
80.0200 8.0000 1.0000
80.0800 2.0000 1.0000
80.1400 3.0000 1.0000
80.2000 2.0000 1.0000
80.2600 3.0000 1.0000
80.3200 2.0000 1.0000
80.3800 5.0000 1.0000
80.4400 5.0000 1.0000
80.5000 6.0000 1.0000
80.5600 7.0000 1.0000
80.6200 9.0000 1.0000
80.6800 6.0000 1.0000
80.7400 5.0000 1.0000
80.8000 6.0000 1.0000
80.8600 6.0000 1.0000
80.9200 3.0000 1.0000
80.9800 8.0000 1.0000
81.0400 4.0000 1.0000
81.1000 2.0000 1.0000
81.1600 6.0000 1.0000
81.2200 6.0000 1.0000
81.2800 3.0000 1.0000
81.3400 7.0000 1.0000
81.4000 8.0000 1.0000
81.4600 2.0000 1.0000
81.5200 0.0000 1.0000
81.5800 3.0000 1.0000
81.6400 4.0000 1.0000
81.7000 5.0000 1.0000
81.7600 7.0000 1.0000
81.8200 6.0000 1.0000
81.8800 2.0000 1.0000
81.9400 3.0000 1.0000
82.0000 3.0000 1.0000
82.0600 8.0000 1.0000
82.1200 13.0000 1.0000
82.1800 7.0000 1.0000
82.2400 1.0000 1.0000
82.3000 4.0000 1.0000
82.3600 7.0000 1.0000
82.4200 5.0000 1.0000
82.4800 7.0000 1.0000
82.5400 3.0000 1.0000
82.6000 2.0000 1.0000
82.6600 2.0000 1.0000
82.7200 6.0000 1.0000
82.7800 10.0000 1.0000
82.8400 2.0000 1.0000
82.9000 8.0000 1.0000
82.9600 7.0000 1.0000
83.0200 2.0000 1.0000
83.0800 6.0000 1.0000
83.1400 0.0000 1.0000
83.2000 7.0000 1.0000
83.2600 5.0000 1.0000
83.3200 6.0000 1.0000
83.3800 4.0000 1.0000
83.4400 8.0000 1.0000
83.5000 7.0000 1.0000
83.5600 3.0000 1.0000
83.6200 4.0000 1.0000
83.6800 4.0000 1.0000
83.7400 7.0000 1.0000
83.8000 5.0000 1.0000
83.8600 5.0000 1.0000
83.9200 0.0000 1.0000
83.9800 3.0000 1.0000
84.0400 7.0000 1.0000
84.1000 2.0000 1.0000
84.1600 2.0000 1.0000
84.2200 8.0000 1.0000
84.2800 7.0000 1.0000
84.3400 5.0000 1.0000
84.4000 5.0000 1.0000
84.4600 10.0000 1.0000
84.5200 8.0000 1.0000
84.5800 2.0000 1.0000
84.6400 2.0000 1.0000
84.7000 6.0000 1.0000
84.7600 6.0000 1.0000
84.8200 7.0000 1.0000
84.8800 4.0000 1.0000
84.9400 7.0000 1.0000
85.0000 3.0000 1.0000
85.0600 6.0000 1.0000
85.1200 4.0000 1.0000
85.1800 3.0000 1.0000
85.2400 6.0000 1.0000
85.3000 2.0000 1.0000
85.3600 3.0000 1.0000
85.4200 3.0000 1.0000
85.4800 2.0000 1.0000
85.5400 4.0000 1.0000
85.6000 4.0000 1.0000
85.6600 0.0000 1.0000
85.7200 6.0000 1.0000
85.7800 6.0000 1.0000
85.8400 3.0000 1.0000
85.9000 0.0000 1.0000
85.9600 5.0000 1.0000
86.0200 2.0000 1.0000
86.0800 2.0000 1.0000
86.1400 2.0000 1.0000
86.2000 2.0000 1.0000
86.2600 2.0000 1.0000
86.3200 4.0000 1.0000
86.3800 4.0000 1.0000
86.4400 6.0000 1.0000
86.5000 4.0000 1.0000
86.5600 4.0000 1.0000
86.6200 4.0000 1.0000
86.6800 4.0000 1.0000
86.7400 2.0000 1.0000
86.8000 6.0000 1.0000
86.8600 3.0000 1.0000
86.9200 3.0000 1.0000
86.9800 3.0000 1.0000
87.0400 6.0000 1.0000
87.1000 2.0000 1.0000
87.1600 2.0000 1.0000
87.2200 5.0000 1.0000
87.2800 1.0000 1.0000
87.3400 2.0000 1.0000
87.4000 4.0000 1.0000
87.4600 4.0000 1.0000
87.5200 6.0000 1.0000
87.5800 5.0000 1.0000
87.6400 7.0000 1.0000
87.7000 5.0000 1.0000
87.7600 4.0000 1.0000
87.8200 4.0000 1.0000
87.8800 8.0000 1.0000
87.9400 4.0000 1.0000
88.0000 2.0000 1.0000
88.0600 6.0000 1.0000
88.1200 7.0000 1.0000
88.1800 3.0000 1.0000
88.2400 5.0000 1.0000
88.3000 0.0000 1.0000
88.3600 2.0000 1.0000
88.4200 2.0000 1.0000
88.4800 7.0000 1.0000
88.5400 7.0000 1.0000
88.6000 8.0000 1.0000
88.6600 3.0000 1.0000
88.7200 2.0000 1.0000
88.7800 6.0000 1.0000
88.8400 4.0000 1.0000
88.9000 5.0000 1.0000
88.9600 4.0000 1.0000
89.0200 6.0000 1.0000
89.0800 2.0000 1.0000
89.1400 3.0000 1.0000
89.2000 1.0000 1.0000
89.2600 5.0000 1.0000
89.3200 5.0000 1.0000
89.3800 2.0000 1.0000
89.4400 4.0000 1.0000
89.5000 8.0000 1.0000
89.5600 2.0000 1.0000
89.6200 4.0000 1.0000
89.6800 2.0000 1.0000
89.7400 7.0000 1.0000
89.8000 2.0000 1.0000
89.8600 6.0000 1.0000
89.9200 5.0000 1.0000
89.9800 1.0000 1.0000
90.0000 4.0000 1.0000
*RAS_INT_END
*RAS_DATA_END